Traceback (most recent call last):
  File "C:\Users\server\github\allprojects\allprojects\disbot\barfile\test.py", line 15, in <module>
    asyncio.run(main('127.0.0.1', 5000))
  File "C:\Users\server\AppData\Local\Programs\Python\Python39\lib\asyncio\runners.py", line 44, in run
    return loop.run_until_complete(main)
  File "C:\Users\server\AppData\Local\Programs\Python\Python39\lib\asyncio\base_events.py", line 629, in run_until_complete
    self.run_forever()
  File "C:\Users\server\AppData\Local\Programs\Python\Python39\lib\asyncio\windows_events.py", line 316, in run_forever
    super().run_forever()
  File "C:\Users\server\AppData\Local\Programs\Python\Python39\lib\asyncio\base_events.py", line 596, in run_forever
    self._run_once()
  File "C:\Users\server\AppData\Local\Programs\Python\Python39\lib\asyncio\base_events.py", line 1854, in _run_once
    event_list = self._selector.select(timeout)
  File "C:\Users\server\AppData\Local\Programs\Python\Python39\lib\asyncio\windows_events.py", line 434, in select
    self._poll(timeout)
  File "C:\Users\server\AppData\Local\Programs\Python\Python39\lib\asyncio\windows_events.py", line 783, in _poll
    status = _overlapped.GetQueuedCompletionStatus(self._iocp, ms)
KeyboardInterrupt
Exception ignored in: <function _ProactorBasePipeTransport.__del__ at 0x000002D7D63C7820>
Traceback (most recent call last):
  File "C:\Users\server\AppData\Local\Programs\Python\Python39\lib\asyncio\proactor_events.py", line 116, in __del__
    self.close()
  File "C:\Users\server\AppData\Local\Programs\Python\Python39\lib\asyncio\proactor_events.py", line 108, in close
    self._loop.call_soon(self._call_connection_lost, None)
  File "C:\Users\server\AppData\Local\Programs\Python\Python39\lib\asyncio\base_events.py", line 746, in call_soon
    self._check_closed()
  File "C:\Users\server\AppData\Local\Programs\Python\Python39\lib\asyncio\base_events.py", line 510, in _check_closed
    raise RuntimeError('Event loop is closed')
RuntimeError: Event loop is closed
^C